2016-04-29 16:51:20,639 - teradata.udaexec - INFO - Initializing UdaExec...
2016-04-29 16:51:20,639 - teradata.udaexec - INFO - Reading config files: ['C:\\etc\\udaexec.ini: Not Found', 'C:\\Users\\TL151006\\udaexec.ini: Not Found', 'C:\\Users\\TL151006\\Desktop\\dev\\trunk\\tests\\sit_jmeter_poc\\tl151006\\test\\udaexec.ini: Not Found']
2016-04-29 16:51:20,639 - teradata.udaexec - INFO - Found run number file: "C:\Users\TL151006\Desktop\dev\trunk\tests\sit_jmeter_poc\tl151006\test\.runNumber"
2016-04-29 16:51:20,639 - teradata.udaexec - INFO - Cleaning up log files older than 90 days.
2016-04-29 16:51:20,639 - teradata.udaexec - INFO - Removed 0 log files.
2016-04-29 16:51:20,639 - teradata.udaexec - INFO - Checkpoint file not found: C:\Users\TL151006\Desktop\dev\trunk\tests\sit_jmeter_poc\tl151006\test\PYTEST.checkpoint
2016-04-29 16:51:20,639 - teradata.udaexec - INFO - No previous checkpoint found, executing from beginning...
2016-04-29 16:51:20,639 - teradata.udaexec - INFO - Execution Details:
/********************************************************************************
 * Application Name: PYTEST
 *          Version: 1.0
 *       Run Number: 20160429165120-11
 *             Host: WUSTL151006-357
 *         Platform: Windows-7-6.1.7601-SP1
 *          OS User: tl151006
 *   Python Version: 3.5.0
 *  Python Compiler: MSC v.1900 64 bit (AMD64)
 *     Python Build: ('v3.5.0:374f501f4567', 'Sep 13 2015 02:27:37')
 *  UdaExec Version: 15.10.0.15
 *     Program Name: test_python.py
 *      Working Dir: C:\Users\TL151006\Desktop\dev\trunk\tests\sit_jmeter_poc\tl151006\test
 *          Log Dir: C:\Users\TL151006\Desktop\dev\trunk\tests\sit_jmeter_poc\tl151006\test\logs
 *         Log File: C:\Users\TL151006\Desktop\dev\trunk\tests\sit_jmeter_poc\tl151006\test\logs\PYTEST.20160429165120-11.log
 *     Config Files: ['C:\\etc\\udaexec.ini: Not Found', 'C:\\Users\\TL151006\\udaexec.ini: Not Found', 'C:\\Users\\TL151006\\Desktop\\dev\\trunk\\tests\\sit_jmeter_poc\\tl151006\\test\\udaexec.ini: Not Found']
 *      Query Bands: ApplicationName=PYTEST;Version=1.0;JobID=20160429165120-11;ClientUser=tl151006;Production=False;udaAppLogFile=C:\Users\TL151006\Desktop\dev\trunk\tests\sit_jmeter_poc\tl151006\test\logs\PYTEST.20160429165120-11.log;UtilityName=PyTd;UtilityVersion=15.10.0.15
********************************************************************************/
2016-04-29 16:51:20,639 - teradata.udaexec - INFO - Creating connection: {'method': 'odbc', 'system': 'monopoly', 'username': 'dbc', 'password': 'XXXXXX'}
2016-04-29 16:51:27,975 - teradata.udaexec - INFO - Connection successful. Duration: 7.335 seconds. Details: {'method': 'odbc', 'system': 'monopoly', 'username': 'dbc', 'password': 'XXXXXX'}
2016-04-29 16:51:29,346 - teradata.udaexec - INFO - Query Successful. Duration: 1.371 seconds, Rows: 44, Query: select TableName, TableKind from DBC.Tables where DatabaseName = 'sit_pdm' and TableKind = 'T'
2016-04-29 16:51:29,762 - teradata.udaexec - INFO - Query Successful. Duration: 0.416 seconds, Rows: 1, Query: show table sit_pdm.ITEM
2016-04-29 16:51:34,390 - root - ERROR - Traceback (most recent call last):
  File "test_python.py", line 212, in <module>
    print(line)
NameError: name 'line' is not defined

2016-04-29 16:51:34,390 - root - INFO - ================== End: Test Failed!] ==================
2016-04-29 16:51:34,390 - teradata.udaexec - INFO - UdaExec exiting.
