2016-04-29 16:42:09,466 - teradata.udaexec - INFO - Initializing UdaExec...
2016-04-29 16:42:09,466 - teradata.udaexec - INFO - Reading config files: ['C:\\etc\\udaexec.ini: Not Found', 'C:\\Users\\TL151006\\udaexec.ini: Not Found', 'C:\\Users\\TL151006\\Desktop\\dev\\trunk\\tests\\sit_jmeter_poc\\tl151006\\test\\udaexec.ini: Not Found']
2016-04-29 16:42:09,466 - teradata.udaexec - INFO - Found run number file: "C:\Users\TL151006\Desktop\dev\trunk\tests\sit_jmeter_poc\tl151006\test\.runNumber"
2016-04-29 16:42:09,466 - teradata.udaexec - INFO - Cleaning up log files older than 90 days.
2016-04-29 16:42:09,466 - teradata.udaexec - INFO - Removed 0 log files.
2016-04-29 16:42:09,481 - teradata.udaexec - INFO - Checkpoint file not found: C:\Users\TL151006\Desktop\dev\trunk\tests\sit_jmeter_poc\tl151006\test\PYTEST.checkpoint
2016-04-29 16:42:09,481 - teradata.udaexec - INFO - No previous checkpoint found, executing from beginning...
2016-04-29 16:42:09,481 - teradata.udaexec - INFO - Execution Details:
/********************************************************************************
 * Application Name: PYTEST
 *          Version: 1.0
 *       Run Number: 20160429164209-8
 *             Host: WUSTL151006-357
 *         Platform: Windows-7-6.1.7601-SP1
 *          OS User: tl151006
 *   Python Version: 3.5.0
 *  Python Compiler: MSC v.1900 64 bit (AMD64)
 *     Python Build: ('v3.5.0:374f501f4567', 'Sep 13 2015 02:27:37')
 *  UdaExec Version: 15.10.0.15
 *     Program Name: test_python.py
 *      Working Dir: C:\Users\TL151006\Desktop\dev\trunk\tests\sit_jmeter_poc\tl151006\test
 *          Log Dir: C:\Users\TL151006\Desktop\dev\trunk\tests\sit_jmeter_poc\tl151006\test\logs
 *         Log File: C:\Users\TL151006\Desktop\dev\trunk\tests\sit_jmeter_poc\tl151006\test\logs\PYTEST.20160429164209-8.log
 *     Config Files: ['C:\\etc\\udaexec.ini: Not Found', 'C:\\Users\\TL151006\\udaexec.ini: Not Found', 'C:\\Users\\TL151006\\Desktop\\dev\\trunk\\tests\\sit_jmeter_poc\\tl151006\\test\\udaexec.ini: Not Found']
 *      Query Bands: ApplicationName=PYTEST;Version=1.0;JobID=20160429164209-8;ClientUser=tl151006;Production=False;udaAppLogFile=C:\Users\TL151006\Desktop\dev\trunk\tests\sit_jmeter_poc\tl151006\test\logs\PYTEST.20160429164209-8.log;UtilityName=PyTd;UtilityVersion=15.10.0.15
********************************************************************************/
2016-04-29 16:42:09,481 - teradata.udaexec - INFO - Creating connection: {'password': 'XXXXXX', 'method': 'odbc', 'username': 'dbc', 'system': 'monopoly'}
2016-04-29 16:42:20,485 - teradata.udaexec - INFO - Connection successful. Duration: 11.004 seconds. Details: {'password': 'XXXXXX', 'method': 'odbc', 'username': 'dbc', 'system': 'monopoly'}
2016-04-29 16:42:20,579 - teradata.udaexec - ERROR - Query Failed! Duration: 0.094 seconds, Query: select TableName, TableKind from DBC.Tables where DatabaseName = 'sit_pdm' where TableKind = 'T'
Traceback (most recent call last):
  File "C:\Users\TL151006\AppData\Local\Programs\Python\Python35\lib\site-packages\teradata\udaexec.py", line 774, in _execute
    func(query, params, **kwargs)
  File "C:\Users\TL151006\AppData\Local\Programs\Python\Python35\lib\site-packages\teradata\tdodbc.py", line 532, in execute
    checkStatus(rc, hStmt=self.hStmt, method="SQLExecDirectW")
  File "C:\Users\TL151006\AppData\Local\Programs\Python\Python35\lib\site-packages\teradata\tdodbc.py", line 206, in checkStatus
    raise DatabaseError(i[2], u"[{}] {}".format(i[0], msg), i[0])
teradata.api.DatabaseError: (3733, '[42000] [Teradata][ODBC Teradata Driver][Teradata Database] The SELECT has more than one WHERE clause. ')
2016-04-29 16:42:41,448 - root - ERROR - Traceback (most recent call last):
  File "test_python.py", line 204, in <module>
    cursor.execute ("select TableName, TableKind from DBC.Tables where DatabaseName = 'sit_pdm' where TableKind = 'T'")
  File "C:\Users\TL151006\AppData\Local\Programs\Python\Python35\lib\site-packages\teradata\udaexec.py", line 730, in execute
    self._execute(self.cursor.execute, query, params, **kwargs)
  File "C:\Users\TL151006\AppData\Local\Programs\Python\Python35\lib\site-packages\teradata\udaexec.py", line 774, in _execute
    func(query, params, **kwargs)
  File "C:\Users\TL151006\AppData\Local\Programs\Python\Python35\lib\site-packages\teradata\tdodbc.py", line 532, in execute
    checkStatus(rc, hStmt=self.hStmt, method="SQLExecDirectW")
  File "C:\Users\TL151006\AppData\Local\Programs\Python\Python35\lib\site-packages\teradata\tdodbc.py", line 206, in checkStatus
    raise DatabaseError(i[2], u"[{}] {}".format(i[0], msg), i[0])
teradata.api.DatabaseError: (3733, '[42000] [Teradata][ODBC Teradata Driver][Teradata Database] The SELECT has more than one WHERE clause. ')

2016-04-29 16:42:41,448 - root - INFO - ================== End: Test Failed!] ==================
2016-04-29 16:42:41,464 - teradata.udaexec - INFO - UdaExec exiting.
