2016-04-29 16:43:26,201 - teradata.udaexec - INFO - Initializing UdaExec...
2016-04-29 16:43:26,201 - teradata.udaexec - INFO - Reading config files: ['C:\\etc\\udaexec.ini: Not Found', 'C:\\Users\\TL151006\\udaexec.ini: Not Found', 'C:\\Users\\TL151006\\Desktop\\dev\\trunk\\tests\\sit_jmeter_poc\\tl151006\\test\\udaexec.ini: Not Found']
2016-04-29 16:43:26,201 - teradata.udaexec - INFO - Found run number file: "C:\Users\TL151006\Desktop\dev\trunk\tests\sit_jmeter_poc\tl151006\test\.runNumber"
2016-04-29 16:43:26,201 - teradata.udaexec - INFO - Cleaning up log files older than 90 days.
2016-04-29 16:43:26,201 - teradata.udaexec - INFO - Removed 0 log files.
2016-04-29 16:43:26,201 - teradata.udaexec - INFO - Checkpoint file not found: C:\Users\TL151006\Desktop\dev\trunk\tests\sit_jmeter_poc\tl151006\test\PYTEST.checkpoint
2016-04-29 16:43:26,216 - teradata.udaexec - INFO - No previous checkpoint found, executing from beginning...
2016-04-29 16:43:26,216 - teradata.udaexec - INFO - Execution Details:
/********************************************************************************
 * Application Name: PYTEST
 *          Version: 1.0
 *       Run Number: 20160429164326-9
 *             Host: WUSTL151006-357
 *         Platform: Windows-7-6.1.7601-SP1
 *          OS User: tl151006
 *   Python Version: 3.5.0
 *  Python Compiler: MSC v.1900 64 bit (AMD64)
 *     Python Build: ('v3.5.0:374f501f4567', 'Sep 13 2015 02:27:37')
 *  UdaExec Version: 15.10.0.15
 *     Program Name: test_python.py
 *      Working Dir: C:\Users\TL151006\Desktop\dev\trunk\tests\sit_jmeter_poc\tl151006\test
 *          Log Dir: C:\Users\TL151006\Desktop\dev\trunk\tests\sit_jmeter_poc\tl151006\test\logs
 *         Log File: C:\Users\TL151006\Desktop\dev\trunk\tests\sit_jmeter_poc\tl151006\test\logs\PYTEST.20160429164326-9.log
 *     Config Files: ['C:\\etc\\udaexec.ini: Not Found', 'C:\\Users\\TL151006\\udaexec.ini: Not Found', 'C:\\Users\\TL151006\\Desktop\\dev\\trunk\\tests\\sit_jmeter_poc\\tl151006\\test\\udaexec.ini: Not Found']
 *      Query Bands: ApplicationName=PYTEST;Version=1.0;JobID=20160429164326-9;ClientUser=tl151006;Production=False;udaAppLogFile=C:\Users\TL151006\Desktop\dev\trunk\tests\sit_jmeter_poc\tl151006\test\logs\PYTEST.20160429164326-9.log;UtilityName=PyTd;UtilityVersion=15.10.0.15
********************************************************************************/
2016-04-29 16:43:26,216 - teradata.udaexec - INFO - Creating connection: {'method': 'odbc', 'username': 'dbc', 'system': 'monopoly', 'password': 'XXXXXX'}
2016-04-29 16:43:40,884 - teradata.udaexec - INFO - Connection successful. Duration: 14.668 seconds. Details: {'method': 'odbc', 'username': 'dbc', 'system': 'monopoly', 'password': 'XXXXXX'}
2016-04-29 16:43:42,685 - teradata.udaexec - INFO - Query Successful. Duration: 1.801 seconds, Rows: 44, Query: select TableName, TableKind from DBC.Tables where DatabaseName = 'sit_pdm' and TableKind = 'T'
2016-04-29 16:43:42,685 - teradata.udaexec - ERROR - Query Failed! Duration: 0.000 seconds, Query: show table 'sit_pdm.ITEM_INVENTORY_PLAN'
Traceback (most recent call last):
  File "C:\Users\TL151006\AppData\Local\Programs\Python\Python35\lib\site-packages\teradata\udaexec.py", line 774, in _execute
    func(query, params, **kwargs)
  File "C:\Users\TL151006\AppData\Local\Programs\Python\Python35\lib\site-packages\teradata\tdodbc.py", line 532, in execute
    checkStatus(rc, hStmt=self.hStmt, method="SQLExecDirectW")
  File "C:\Users\TL151006\AppData\Local\Programs\Python\Python35\lib\site-packages\teradata\tdodbc.py", line 206, in checkStatus
    raise DatabaseError(i[2], u"[{}] {}".format(i[0], msg), i[0])
teradata.api.DatabaseError: (3707, "[42000] [Teradata][ODBC Teradata Driver][Teradata Database] Syntax error, expected something like a name or a Unicode delimited identifier or an 'UDFCALLNAME' keyword between the 'table' keyword and the string 'sit_pdm.ITEM_INVENTORY_PLAN'. ")
2016-04-29 16:43:52,272 - root - ERROR - Traceback (most recent call last):
  File "test_python.py", line 209, in <module>
    cursor.execute ("show table 'sit_pdm.%s'" % (k))
  File "C:\Users\TL151006\AppData\Local\Programs\Python\Python35\lib\site-packages\teradata\udaexec.py", line 730, in execute
    self._execute(self.cursor.execute, query, params, **kwargs)
  File "C:\Users\TL151006\AppData\Local\Programs\Python\Python35\lib\site-packages\teradata\udaexec.py", line 774, in _execute
    func(query, params, **kwargs)
  File "C:\Users\TL151006\AppData\Local\Programs\Python\Python35\lib\site-packages\teradata\tdodbc.py", line 532, in execute
    checkStatus(rc, hStmt=self.hStmt, method="SQLExecDirectW")
  File "C:\Users\TL151006\AppData\Local\Programs\Python\Python35\lib\site-packages\teradata\tdodbc.py", line 206, in checkStatus
    raise DatabaseError(i[2], u"[{}] {}".format(i[0], msg), i[0])
teradata.api.DatabaseError: (3707, "[42000] [Teradata][ODBC Teradata Driver][Teradata Database] Syntax error, expected something like a name or a Unicode delimited identifier or an 'UDFCALLNAME' keyword between the 'table' keyword and the string 'sit_pdm.ITEM_INVENTORY_PLAN'. ")

2016-04-29 16:43:52,272 - root - INFO - ================== End: Test Failed!] ==================
2016-04-29 16:43:52,272 - teradata.udaexec - INFO - UdaExec exiting.
